<?xml version="1.0" ?>
<robot name="mobile_robot_ust" xmlns:xacro="http://www.ros.org/wiki/xacro">

<xacro:include filename="$(find mobile_robot_ust_description)/urdf/materials.xacro" />
<!-- <xacro:include filename="$(find mobile_robot_ust_description)/urdf/mobile_robot_ust.trans" /> -->
<xacro:include filename="$(find mobile_robot_ust_description)/urdf/mobile_robot_ust.gazebo" />

<link name="base_footprint"/>
<joint name="base_joint" type="fixed">
    <origin xyz="0 0 0" rpy="0 0 0" />
    <parent link="base_footprint"/>
    <child link="base_link" />
</joint>

<link name="base_link">
  <inertial>
    <origin rpy="0 0 0" xyz="1.1224367674413892e-05 -0.0011745211304902412 0.09345651897280045"/>
    <mass value="91.75920794269815"/>
    <inertia ixx="2.445112" ixy="-0.0" ixz="6.3e-05" iyy="2.327332" iyz="0.0" izz="4.289617"/>
  </inertial>
  <visual>
    <origin rpy="0 0 0" xyz="0 0 0"/>
    <geometry>
      <mesh filename="package://mobile_robot_ust_description/meshes/base_link.stl" scale="0.001 0.001 0.001"/>
    </geometry>
    <material name="silver"/>
  </visual>
  <collision>
    <origin rpy="0 0 0" xyz="0 0 0"/>
    <geometry>
      <mesh filename="package://mobile_robot_ust_description/meshes/base_link.stl" scale="0.001 0.001 0.001"/>
    </geometry>
  </collision>
</link>

<link name="left__motor_1_1">
  <inertial>
    <origin rpy="0 0 0" xyz="0.11672239487013364 -0.012131401668074094 0.0012656553309385726"/>
    <mass value="0.6244105331159368"/>
    <inertia ixx="0.000346" ixy="-7.8e-05" ixz="-0.0" iyy="0.000322" iyz="-0.0" izz="0.000476"/>
  </inertial>
  <visual>
    <origin rpy="0 0 0" xyz="-0.0 0.002349 -0.064969"/>
    <geometry>
      <mesh filename="package://mobile_robot_ust_description/meshes/left__motor_1_1.stl" scale="0.001 0.001 0.001"/>
    </geometry>
    <material name="silver"/>
  </visual>
  <collision>
    <origin rpy="0 0 0" xyz="-0.0 0.002349 -0.064969"/>
    <geometry>
      <mesh filename="package://mobile_robot_ust_description/meshes/left__motor_1_1.stl" scale="0.001 0.001 0.001"/>
    </geometry>
  </collision>
</link>

<link name="right_motor_1_1">
  <inertial>
    <origin rpy="0 0 0" xyz="0.003277605930476421 0.014480359001265061 0.0012656553166721929"/>
    <mass value="0.624410471996312"/>
    <inertia ixx="0.000346" ixy="-7.8e-05" ixz="0.0" iyy="0.000322" iyz="0.0" izz="0.000476"/>
  </inertial>
  <visual>
    <origin rpy="0 0 0" xyz="0.12 0.002349 -0.064969"/>
    <geometry>
      <mesh filename="package://mobile_robot_ust_description/meshes/right_motor_1_1.stl" scale="0.001 0.001 0.001"/>
    </geometry>
    <material name="silver"/>
  </visual>
  <collision>
    <origin rpy="0 0 0" xyz="0.12 0.002349 -0.064969"/>
    <geometry>
      <mesh filename="package://mobile_robot_ust_description/meshes/right_motor_1_1.stl" scale="0.001 0.001 0.001"/>
    </geometry>
  </collision>
</link>

<link name="right_wheel_1_1">
  <inertial>
    <origin rpy="0 0 0" xyz="0.020651625000002477 4.788695097536315e-07 -3.394465878520103e-07"/>
    <mass value="1.7115433383420557"/>
    <inertia ixx="0.004743" ixy="-0.0" ixz="-0.0" iyy="0.002492" iyz="0.0" izz="0.002492"/>
  </inertial>
  <visual>
    <origin rpy="0 0 0" xyz="0.1786 0.001925 -0.066235"/>
    <geometry>
      <mesh filename="package://mobile_robot_ust_description/meshes/right_wheel_1_1.stl" scale="0.001 0.001 0.001"/>
    </geometry>
    <material name="silver"/>
  </visual>
  <collision>
    <origin rpy="0 0 0" xyz="0.1786 0.001925 -0.066235"/>
    <geometry>
      <mesh filename="package://mobile_robot_ust_description/meshes/right_wheel_1_1.stl" scale="0.001 0.001 0.001"/>
    </geometry>
  </collision>
</link>

<link name="left_wheel_1_1">
  <inertial>
    <origin rpy="0 0 0" xyz="-0.02065162509005472 4.78699054116342e-07 -3.35564306092051e-07"/>
    <mass value="1.7115433457205622"/>
    <inertia ixx="0.004743" ixy="-0.0" ixz="0.0" iyy="0.002492" iyz="0.0" izz="0.002492"/>
  </inertial>
  <visual>
    <origin rpy="0 0 0" xyz="-0.1786 0.000425 -0.066235"/>
    <geometry>
      <mesh filename="package://mobile_robot_ust_description/meshes/left_wheel_1_1.stl" scale="0.001 0.001 0.001"/>
    </geometry>
    <material name="silver"/>
  </visual>
  <collision>
    <origin rpy="0 0 0" xyz="-0.1786 0.000425 -0.066235"/>
    <geometry>
      <mesh filename="package://mobile_robot_ust_description/meshes/left_wheel_1_1.stl" scale="0.001 0.001 0.001"/>
    </geometry>
  </collision>
</link>

<link name="castor_wheel_1">
  <inertial>
    <origin rpy="0 0 0" xyz="1.371325051413342e-15 0.19117447886950983 -0.03306783712774608"/>
    <mass value="0.3227046646676664"/>
    <inertia ixx="6e-05" ixy="0.0" ixz="0.0" iyy="6e-05" iyz="0.0" izz="9.6e-05"/>
  </inertial>
  <visual>
    <origin rpy="0 0 0" xyz="-0.0 0.002349 -0.044969"/>
    <geometry>
      <mesh filename="package://mobile_robot_ust_description/meshes/castor_wheel_1.stl" scale="0.001 0.001 0.001"/>
    </geometry>
    <material name="silver"/>
  </visual>
  <collision>
    <origin rpy="0 0 0" xyz="-0.0 0.002349 -0.044969"/>
    <geometry>
      <mesh filename="package://mobile_robot_ust_description/meshes/castor_wheel_1.stl" scale="0.001 0.001 0.001"/>
    </geometry>
  </collision>
</link>

<joint name="Rigid2" type="fixed">
  <origin rpy="0 0 0" xyz="0.0 -0.002349 0.064969"/>
  <parent link="base_link"/>
  <child link="left__motor_1_1"/>
</joint>

<joint name="Rigid3" type="fixed">
  <origin rpy="0 0 0" xyz="-0.12 -0.002349 0.064969"/>
  <parent link="base_link"/>
  <child link="right_motor_1_1"/>
</joint>

<joint name="Rev4" type="continuous">
  <origin rpy="0 0 0" xyz="-0.0586 0.000424 0.001266"/>
  <parent link="right_motor_1_1"/>
  <child link="right_wheel_1_1"/>
  <axis xyz="-1.0 0.0 -0.0"/>
</joint>

<joint name="Rev5" type="continuous">
  <origin rpy="0 0 0" xyz="0.1786 0.001924 0.001266"/>
  <parent link="left__motor_1_1"/>
  <child link="left_wheel_1_1"/>
  <axis xyz="1.0 0.0 0.0"/>
</joint>

<joint name="Rigid6" type="fixed">
  <origin rpy="0 0 0" xyz="0.0 -0.002349 0.044969"/>
  <parent link="base_link"/>
  <child link="castor_wheel_1"/>
</joint>

<link name="base_scan">
  <inertial>
    <mass value="1e-5"/>
    <origin xyz="0 0 0" rpy="0 0 0"/>
    <inertia
        ixx="1e-6" ixy="0" ixz="0"
        iyy="1e-6" iyz="0"
        izz="1e-6"/>
  </inertial>

  <visual>
    <origin xyz="0 0 0" rpy="0 0 0"/>
    <geometry>
        <!-- <box size="0.1 0.1 0.1"/> -->
        <mesh filename="package://test_slam/meshes/sensors/hokuyo.dae"/>
    </geometry>
  </visual>

  <collision>
    <origin xyz="0 0 0" rpy="0 0 0" />
    <geometry>
        <box size="0.05 0.05 0.05"/>
    </geometry>
  </collision>
</link>

<joint type="fixed" name="scan_joint">
  <origin xyz="0.5 0 0.125" rpy="0 0 0"/> <!--0.15 0 0.125-->
  <child link="base_scan"/>
  <parent link="base_link"/>
  <axis xyz="0 1 0" rpy="0 0 0"/>
</joint>

</robot>
